from pysys.basetest import BaseTest

"""
Validate tedge-mapper can't be started twice.


Given unconnected system

When we start first tedge-mapper it runs uninterrupted
When we start second tedge-mapper it doesn't connect to broker and exits with code 1 and logs error message

Then we validate output appropriate error message

"""


class RuntimeMultiMappers(BaseTest):
    def execute(self):
        tedge_mapper = "/usr/bin/tedge-mapper"
        self.sudo = "/usr/bin/sudo"

        # starting the first tedge mapper instance
        _ = self.startProcess(
            command=self.sudo,
            arguments=["systemctl", "start", "tedge-mapper-c8y"],
            stdouterr="tedge_mapper1",
        )

        self.wait(0.1)

        # starting the second tedge mapper instance
        # and expecting this one to crash
        _ = self.startProcess(
            command=self.sudo,
            arguments=["-u", "tedge", tedge_mapper, "c8y"],
            stdouterr="tedge_mapper2",
            expectedExitStatus="==1",
        )

        # stopping the first tedge mapper instance
        _ = self.startProcess(
            command=self.sudo,
            arguments=["systemctl", "stop", "tedge-mapper-c8y"],
            stdouterr="tedge_mapper1",
        )

    def validate(self):
        self.assertGrep(
            "tedge_mapper2.err", "Error: Couldn't acquire file lock.", contains=True
        )
